<sdf version='1.7'>
  <world name='default'>
    <light name='sun' type='directional'>
      <cast_shadows>1</cast_shadows>
      <pose>0 0 10 0 -0 0</pose>
      <diffuse>0.8 0.8 0.8 1</diffuse>
      <specular>0.2 0.2 0.2 1</specular>
      <attenuation>
        <range>1000</range>
        <constant>0.9</constant>
        <linear>0.01</linear>
        <quadratic>0.001</quadratic>
      </attenuation>
      <direction>-0.5 0.1 -0.9</direction>
      <spot>
        <inner_angle>0</inner_angle>
        <outer_angle>0</outer_angle>
        <falloff>0</falloff>
      </spot>
    </light>
    <model name='ground_plane'>
      <static>1</static>
      <link name='link'>
        <collision name='collision'>
          <geometry>
            <plane>
              <normal>0 0 1</normal>
              <size>100 100</size>
            </plane>
          </geometry>
          <surface>
            <contact>
              <collide_bitmask>65535</collide_bitmask>
              <ode/>
            </contact>
            <friction>
              <ode>
                <mu>100</mu>
                <mu2>50</mu2>
              </ode>
              <torsional>
                <ode/>
              </torsional>
            </friction>
            <bounce/>
          </surface>
          <max_contacts>10</max_contacts>
        </collision>
        <visual name='visual'>
          <cast_shadows>0</cast_shadows>
          <geometry>
            <plane>
              <normal>0 0 1</normal>
              <size>100 100</size>
            </plane>
          </geometry>
          <material>
            <script>
              <uri>file://media/materials/scripts/gazebo.material</uri>
              <name>Gazebo/Grey</name>
            </script>
          </material>
        </visual>
        <self_collide>0</self_collide>
        <enable_wind>0</enable_wind>
        <kinematic>0</kinematic>
      </link>
    </model>
    <gravity>0 0 -9.8</gravity>
    <magnetic_field>6e-06 2.3e-05 -4.2e-05</magnetic_field>
    <atmosphere type='adiabatic'/>
    <physics type='ode'>
      <max_step_size>0.001</max_step_size>
      <real_time_factor>1</real_time_factor>
      <real_time_update_rate>1000</real_time_update_rate>
    </physics>
    <scene>
      <ambient>0.4 0.4 0.4 1</ambient>
      <background>0.7 0.7 0.7 1</background>
      <shadows>1</shadows>
    </scene>
    <wind/>
    <spherical_coordinates>
      <surface_model>EARTH_WGS84</surface_model>
      <latitude_deg>0</latitude_deg>
      <longitude_deg>0</longitude_deg>
      <elevation>0</elevation>
      <heading_deg>0</heading_deg>
    </spherical_coordinates>
    <model name='table'>
      <static>1</static>
      <link name='link'>
        <collision name='surface'>
          <pose>0 0 1 0 -0 0</pose>
          <geometry>
            <box>
              <size>1.5 0.8 0.03</size>
            </box>
          </geometry>
          <surface>
            <friction>
              <ode>
                <mu>0.6</mu>
                <mu2>0.6</mu2>
              </ode>
              <torsional>
                <ode/>
              </torsional>
            </friction>
            <contact>
              <ode/>
            </contact>
            <bounce/>
          </surface>
          <max_contacts>10</max_contacts>
        </collision>
        <visual name='visual1'>
          <pose>0 0 1 0 -0 0</pose>
          <geometry>
            <box>
              <size>1.5 0.8 0.03</size>
            </box>
          </geometry>
          <material>
            <script>
              <uri>file://media/materials/scripts/gazebo.material</uri>
              <name>Gazebo/Wood</name>
            </script>
          </material>
        </visual>
        <collision name='front_left_leg'>
          <pose>0.68 0.38 0.5 0 -0 0</pose>
          <geometry>
            <cylinder>
              <radius>0.02</radius>
              <length>1</length>
            </cylinder>
          </geometry>
          <max_contacts>10</max_contacts>
          <surface>
            <contact>
              <ode/>
            </contact>
            <bounce/>
            <friction>
              <torsional>
                <ode/>
              </torsional>
              <ode/>
            </friction>
          </surface>
        </collision>
        <visual name='front_left_leg'>
          <pose>0.68 0.38 0.5 0 -0 0</pose>
          <geometry>
            <cylinder>
              <radius>0.02</radius>
              <length>1</length>
            </cylinder>
          </geometry>
          <material>
            <script>
              <uri>file://media/materials/scripts/gazebo.material</uri>
              <name>Gazebo/Grey</name>
            </script>
          </material>
        </visual>
        <collision name='front_right_leg'>
          <pose>0.68 -0.38 0.5 0 -0 0</pose>
          <geometry>
            <cylinder>
              <radius>0.02</radius>
              <length>1</length>
            </cylinder>
          </geometry>
          <max_contacts>10</max_contacts>
          <surface>
            <contact>
              <ode/>
            </contact>
            <bounce/>
            <friction>
              <torsional>
                <ode/>
              </torsional>
              <ode/>
            </friction>
          </surface>
        </collision>
        <visual name='front_right_leg'>
          <pose>0.68 -0.38 0.5 0 -0 0</pose>
          <geometry>
            <cylinder>
              <radius>0.02</radius>
              <length>1</length>
            </cylinder>
          </geometry>
          <material>
            <script>
              <uri>file://media/materials/scripts/gazebo.material</uri>
              <name>Gazebo/Grey</name>
            </script>
          </material>
        </visual>
        <collision name='back_right_leg'>
          <pose>-0.68 -0.38 0.5 0 -0 0</pose>
          <geometry>
            <cylinder>
              <radius>0.02</radius>
              <length>1</length>
            </cylinder>
          </geometry>
          <max_contacts>10</max_contacts>
          <surface>
            <contact>
              <ode/>
            </contact>
            <bounce/>
            <friction>
              <torsional>
                <ode/>
              </torsional>
              <ode/>
            </friction>
          </surface>
        </collision>
        <visual name='back_right_leg'>
          <pose>-0.68 -0.38 0.5 0 -0 0</pose>
          <geometry>
            <cylinder>
              <radius>0.02</radius>
              <length>1</length>
            </cylinder>
          </geometry>
          <material>
            <script>
              <uri>file://media/materials/scripts/gazebo.material</uri>
              <name>Gazebo/Grey</name>
            </script>
          </material>
        </visual>
        <collision name='back_left_leg'>
          <pose>-0.68 0.38 0.5 0 -0 0</pose>
          <geometry>
            <cylinder>
              <radius>0.02</radius>
              <length>1</length>
            </cylinder>
          </geometry>
          <max_contacts>10</max_contacts>
          <surface>
            <contact>
              <ode/>
            </contact>
            <bounce/>
            <friction>
              <torsional>
                <ode/>
              </torsional>
              <ode/>
            </friction>
          </surface>
        </collision>
        <visual name='back_left_leg'>
          <pose>-0.68 0.38 0.5 0 -0 0</pose>
          <geometry>
            <cylinder>
              <radius>0.02</radius>
              <length>1</length>
            </cylinder>
          </geometry>
          <material>
            <script>
              <uri>file://media/materials/scripts/gazebo.material</uri>
              <name>Gazebo/Grey</name>
            </script>
          </material>
        </visual>
        <self_collide>0</self_collide>
        <enable_wind>0</enable_wind>
        <kinematic>0</kinematic>
      </link>
      <pose>0.55681 -0.604908 0 0 -0 0</pose>
    </model>
    <model name='cube_Logo'>
      <link name='link'>
        <pose>0 0 0 0 -0 0</pose>
        <collision name='collision'>
          <geometry>
            <mesh>
              <uri>model://cube_logo/meshes/logo_cube.obj</uri>
              <scale>0.5 0.5 0.5</scale>
            </mesh>
          </geometry>
          <max_contacts>10</max_contacts>
          <surface>
            <contact>
              <ode/>
            </contact>
            <bounce/>
            <friction>
              <torsional>
                <ode/>
              </torsional>
              <ode/>
            </friction>
          </surface>
        </collision>
        <visual name='visual'>
          <geometry>
            <mesh>
              <uri>model://cube_logo/meshes/logo_cube.obj</uri>
              <scale>0.5 0.5 0.5</scale>
            </mesh>
          </geometry>
        </visual>
        <self_collide>0</self_collide>
        <inertial>
          <pose>0 0 0 0 -0 0</pose>
          <inertia>
            <ixx>1</ixx>
            <ixy>0</ixy>
            <ixz>0</ixz>
            <iyy>1</iyy>
            <iyz>0</iyz>
            <izz>1</izz>
          </inertia>
          <mass>1</mass>
        </inertial>
        <enable_wind>0</enable_wind>
        <kinematic>0</kinematic>
      </link>
      <pose>0.38689 -0.463076 0 0 -0 0</pose>
    </model>
    <model name='cube_M'>
      <link name='link'>
        <pose>0 0 0 0 -0 0</pose>
        <collision name='collision'>
          <geometry>
            <mesh>
              <uri>model://cube_m/meshes/M.obj</uri>
              <scale>0.5 0.5 0.5</scale>
            </mesh>
          </geometry>
          <max_contacts>10</max_contacts>
          <surface>
            <contact>
              <ode/>
            </contact>
            <bounce/>
            <friction>
              <torsional>
                <ode/>
              </torsional>
              <ode/>
            </friction>
          </surface>
        </collision>
        <visual name='visual'>
          <geometry>
            <mesh>
              <uri>model://cube_m/meshes/M.obj</uri>
              <scale>0.5 0.5 0.5</scale>
            </mesh>
          </geometry>
        </visual>
        <self_collide>0</self_collide>
        <inertial>
          <pose>0 0 0 0 -0 0</pose>
          <inertia>
            <ixx>0.167</ixx>
            <ixy>0</ixy>
            <ixz>0</ixz>
            <iyy>0.167</iyy>
            <iyz>0</iyz>
            <izz>0.167</izz>
          </inertia>
          <mass>4</mass>
        </inertial>
        <enable_wind>0</enable_wind>
        <kinematic>0</kinematic>
      </link>
      <pose>0.056138 -0.937535 0 0 -0 0</pose>
    </model>
    <model name='cube_U'>
      <link name='link'>
        <pose>0 0 0 0 -0 0</pose>
        <collision name='collision'>
          <geometry>
            <mesh>
              <uri>model://cube_u/meshes/U.obj</uri>
              <scale>0.5 0.5 0.5</scale>
            </mesh>
          </geometry>
          <max_contacts>10</max_contacts>
          <surface>
            <contact>
              <ode/>
            </contact>
            <bounce/>
            <friction>
              <torsional>
                <ode/>
              </torsional>
              <ode/>
            </friction>
          </surface>
        </collision>
        <visual name='visual'>
          <geometry>
            <mesh>
              <uri>model://cube_u/meshes/U.obj</uri>
              <scale>0.5 0.5 0.5</scale>
            </mesh>
          </geometry>
        </visual>
        <self_collide>0</self_collide>
        <inertial>
          <pose>0 0 0 0 -0 0</pose>
          <inertia>
            <ixx>0.167</ixx>
            <ixy>0</ixy>
            <ixz>0</ixz>
            <iyy>0.167</iyy>
            <iyz>0</iyz>
            <izz>0.167</izz>
          </inertia>
          <mass>4</mass>
        </inertial>
        <enable_wind>0</enable_wind>
        <kinematic>0</kinematic>
      </link>
      <pose>-0.023334 -1.38697 0 0 -0 0</pose>
    </model>
    <state world_name='default'>
      <sim_time>11192 974000000</sim_time>
      <real_time>9705 709073917</real_time>
      <wall_time>1703870922 647272922</wall_time>
      <iterations>9697298</iterations>
      <model name='cube_Logo'>
        <pose>0.45 0.25 1.08341 1e-06 -0 1.6e-05</pose>
        <scale>1 1 1</scale>
        <link name='link'>
          <pose>0.45 0.25 1.08341 1e-06 -0 1.6e-05</pose>
          <velocity>0 0 0 0 -0 0</velocity>
          <acceleration>-0.011544 -0.055282 19.6472 0.803887 -0.164413 0.003983</acceleration>
          <wrench>-0.011544 -0.055282 19.6472 0 -0 0</wrench>
        </link>
      </model>
      <model name='cube_M'>
        <pose>0.605093 -0.016199 1.08435 3.12772 -4e-06 -1.58184</pose>
        <scale>1 1 1</scale>
        <link name='link'>
          <pose>0.605093 -0.016199 1.08435 3.12772 -4e-06 -1.58184</pose>
          <velocity>0 0 0 0 -0 0</velocity>
          <acceleration>2.58788 0.417621 -7.90496 2.51824 1.11174 -2.77142</acceleration>
          <wrench>10.3515 1.67048 -31.6198 0 -0 0</wrench>
        </link>
      </model>
      <model name='cube_U'>
        <pose>0.468906 -0.307854 1.0834 0 -0 1.57635</pose>
        <scale>1 1 1</scale>
        <link name='link'>
          <pose>0.468906 -0.307854 1.0834 0 -0 1.57635</pose>
          <velocity>0 0 0 0 -0 0</velocity>
          <acceleration>0 0 -9.8 0 -0 0</acceleration>
          <wrench>0 0 -39.2 0 -0 0</wrench>
        </link>
      </model>
      <model name='ground_plane'>
        <pose>0 0 0 0 -0 0</pose>
        <scale>1 1 1</scale>
        <link name='link'>
          <pose>0 0 0 0 -0 0</pose>
          <velocity>0 0 0 0 -0 0</velocity>
          <acceleration>0 0 0 0 -0 0</acceleration>
          <wrench>0 0 0 0 -0 0</wrench>
        </link>
      </model>
      <model name='robot'>
        <pose>-0 0 0 0 -0 0</pose>
        <scale>1 1 1</scale>
        <link name='base_link'>
          <pose>-0 0 1.02 3.5e-05 0.000102 1e-06</pose>
          <velocity>0 -0 0 2e-06 -1e-06 -0</velocity>
          <acceleration>1e-06 -2e-06 1.2e-05 0.003745 -0.001821 -0.000526</acceleration>
          <wrench>5e-06 -8e-06 4.9e-05 0 -0 0</wrench>
        </link>
        <link name='forearm_link'>
          <pose>-0.424841 0.016248 1.12018 -0.000132 -7.1e-05 -0.000239</pose>
          <velocity>-0.000316 0.000116 -0.012372 -6e-06 -0.029544 -0.000274</velocity>
          <acceleration>0.000331 -0.00057 -0.000197 -0.008471 0.002008 0.003321</acceleration>
          <wrench>0.000752 -0.001297 -0.000448 0 -0 0</wrench>
        </link>
        <link name='left_inner_finger'>
          <pose>-0.165411 0.073384 1.60934 -0.017625 1.56208 -0.026493</pose>
          <velocity>-0.014881 4.4e-05 -0.004362 -5.9e-05 -0.030868 -0.000275</velocity>
          <acceleration>0.001333 0.002007 -0.000808 -0.006833 0.002791 0.000123</acceleration>
          <wrench>6.7e-05 0.0001 -4e-05 0 -0 0</wrench>
        </link>
        <link name='left_inner_knuckle'>
          <pose>-0.201163 0.099645 1.60902 -0.51763 1.56208 -0.026498</pose>
          <velocity>-0.014864 5.3e-05 -0.005467 -5.9e-05 -0.030868 -0.000284</velocity>
          <acceleration>0.001324 0.002021 -0.000582 -0.006918 0.002685 0.000232</acceleration>
          <wrench>6.6e-05 0.000101 -2.9e-05 0 -0 0</wrench>
        </link>
        <link name='left_outer_knuckle'>
          <pose>-0.217746 0.090291 1.60888 -0.517641 1.56208 -0.026509</pose>
          <velocity>-0.014862 5.8e-05 -0.005979 -5.9e-05 -0.030868 -0.000279</velocity>
          <acceleration>0.001342 0.00197 -0.000605 -0.006769 0.002813 0.000123</acceleration>
          <wrench>6.7e-05 9.9e-05 -3e-05 0 -0 0</wrench>
        </link>
        <link name='rear_camera_link'>
          <pose>-1 0 1.8 0 0.2967 0</pose>
          <velocity>0 0 0 0 -0 0</velocity>
          <acceleration>0 0 0 0 -0 0</acceleration>
          <wrench>0 0 0 0 -0 0</wrench>
        </link>
        <link name='right_inner_finger'>
          <pose>-0.164815 0.140622 1.60933 0.017695 -1.56208 3.11503</pose>
          <velocity>-0.014861 4.2e-05 -0.004348 -5.9e-05 -0.030868 -0.000248</velocity>
          <acceleration>0.00133 0.001968 -0.000517 -0.006748 0.002761 0.000143</acceleration>
          <wrench>6.7e-05 9.8e-05 -2.6e-05 0 -0 0</wrench>
        </link>
        <link name='right_inner_knuckle'>
          <pose>-0.201027 0.115 1.60902 -0.482364 -1.56208 3.1151</pose>
          <velocity>-0.014859 5.3e-05 -0.005464 -5.9e-05 -0.030868 -0.000287</velocity>
          <acceleration>0.001319 0.002024 -0.000513 -0.006925 0.002666 0.000247</acceleration>
          <wrench>6.6e-05 0.000101 -2.6e-05 0 -0 0</wrench>
        </link>
        <link name='right_outer_knuckle'>
          <pose>-0.217441 0.124646 1.60887 -0.482388 -1.56208 3.11511</pose>
          <velocity>-0.014852 5.8e-05 -0.005971 -5.9e-05 -0.030868 -0.000306</velocity>
          <acceleration>0.001312 0.002035 -0.00042 -0.006965 0.002629 0.000292</acceleration>
          <wrench>6.6e-05 0.000102 -2.1e-05 0 -0 0</wrench>
        </link>
        <link name='shoulder_link'>
          <pose>1.4e-05 -5e-06 1.10916 -6.5e-05 -0.000194 -0.000235</pose>
          <velocity>-0 -0 0 -4e-06 2e-06 -0.000279</velocity>
          <acceleration>-0.000376 -0.000641 -1.2e-05 -0.007362 0.003311 0.000544</acceleration>
          <wrench>-0.001392 -0.002373 -4.5e-05 0 -0 0</wrench>
        </link>
        <link name='upper_arm_link'>
          <pose>4.6e-05 0.135845 1.10914 -0.004853 -1.54486 0.004615</pose>
          <velocity>3.8e-05 -0 -1e-06 -8e-06 -0.029119 -0.000274</velocity>
          <acceleration>-0.000282 -0.0009 -0.000995 -0.204625 0.002137 0.005116</acceleration>
          <wrench>-0.002366 -0.007557 -0.008349 0 -0 0</wrench>
        </link>
        <link name='wrist_1_link'>
          <pose>-0.42487 0.0163 1.51243 -0.000136 -0.00872 -0.000232</pose>
          <velocity>-0.011905 0.000118 -0.012373 -5e-06 -0.030868 -0.000275</velocity>
          <acceleration>0.001058 0.001624 0.000169 -0.007424 0.002467 0.000279</acceleration>
          <wrench>0.00129 0.001979 0.000206 0 -0 0</wrench>
        </link>
        <link name='wrist_2_link'>
          <pose>-0.424849 0.1093 1.51241 0.008722 -6.1e-05 -1.57966</pose>
          <velocity>-0.011879 0.000118 -0.012373 -5e-06 -0.030868 -0.000293</velocity>
          <acceleration>0.001345 0.002191 8.3e-05 -0.007158 0.002563 0.00025</acceleration>
          <wrench>0.001639 0.002671 0.000101 0 -0 0</wrench>
        </link>
        <link name='wrist_3_link'>
          <pose>-0.425674 0.109313 1.60706 0.008722 -0.000153 -1.57966</pose>
          <velocity>-0.014801 0.000119 -0.012398 -5.9e-05 -0.030868 -0.000294</velocity>
          <acceleration>0.001319 0.002019 -0.000106 -0.007438 0.00248 0.000255</acceleration>
          <wrench>0.001171 0.001793 -9.4e-05 0 -0 0</wrench>
        </link>
      </model>
      <model name='table'>
        <pose>0.6 0 0 0 -0 0</pose>
        <scale>1 1 1</scale>
        <link name='link'>
          <pose>0.6 0 0 0 -0 0</pose>
          <velocity>0 0 0 0 -0 0</velocity>
          <acceleration>0 0 0 0 -0 0</acceleration>
          <wrench>0 0 0 0 -0 0</wrench>
        </link>
      </model>
      <light name='sun'>
        <pose>0 0 10 0 -0 0</pose>
      </light>
    </state>
    <gui fullscreen='0'>
      <camera name='user_camera'>
        <pose>-1.97272 -2.82497 3.53668 0 0.617796 0.89214</pose>
        <view_controller>orbit</view_controller>
        <projection_type>perspective</projection_type>
      </camera>
    </gui>
    <model name='robot'>
      <joint name='rear_camera_joint' type='fixed'>
        <pose relative_to='__model__'>-1 0 1.8 0 0.2967 0</pose>
        <parent>world</parent>
        <child>rear_camera_link</child>
      </joint>
      <link name='rear_camera_link'>
        <pose relative_to='rear_camera_joint'>0 0 0 0 -0 0</pose>
        <inertial>
          <pose>0 0 0 0 -0 0</pose>
          <mass>0.1</mass>
          <inertia>
            <ixx>0.0001</ixx>
            <ixy>0</ixy>
            <ixz>0</ixz>
            <iyy>0.0001</iyy>
            <iyz>0</iyz>
            <izz>0.0001</izz>
          </inertia>
        </inertial>
        <collision name='rear_camera_link_collision'>
          <pose>0 0 0 0 -0 0</pose>
          <geometry>
            <box>
              <size>0.1 0.1 0.1</size>
            </box>
          </geometry>
          <surface>
            <contact>
              <ode/>
            </contact>
            <friction>
              <ode/>
              <torsional>
                <ode/>
              </torsional>
            </friction>
            <bounce/>
          </surface>
          <max_contacts>10</max_contacts>
        </collision>
        <visual name='rear_camera_link_visual'>
          <pose>0 0 0 0 -0 0</pose>
          <geometry>
            <box>
              <size>0.1 0.1 0.1</size>
            </box>
          </geometry>
        </visual>
        <sensor name='rear_camera_sensor' type='camera'>
          <update_rate>30</update_rate>
          <visualize>1</visualize>
          <camera name='head'>
            <horizontal_fov>1.39626</horizontal_fov>
            <image>
              <width>640</width>
              <height>480</height>
              <format>R8G8B8</format>
            </image>
            <clip>
              <near>0.02</near>
              <far>300</far>
            </clip>
          </camera>
          <plugin name='camera_controller' filename='libgazebo_ros_camera.so'>
            <alwaysOn>1</alwaysOn>
            <updateRate>0</updateRate>
            <cameraName>rear_camera</cameraName>
            <imageTopicName>rear_camera/image_raw</imageTopicName>
            <cameraInfoTopicName>rear_camera/camera_info</cameraInfoTopicName>
            <frameName>rear_camera_link</frameName>
            <robotNamespace>/</robotNamespace>
          </plugin>
        </sensor>
        <self_collide>0</self_collide>
        <enable_wind>0</enable_wind>
        <kinematic>0</kinematic>
      </link>
      <joint name='world_base_joint' type='fixed'>
        <pose relative_to='__model__'>0 0 1.02 0 -0 0</pose>
        <parent>world</parent>
        <child>base_link</child>
      </joint>
      <link name='base_link'>
        <pose relative_to='world_base_joint'>0 0 0 0 -0 0</pose>
        <inertial>
          <pose>0 0 0 0 -0 0</pose>
          <mass>4</mass>
          <inertia>
            <ixx>0.004433</ixx>
            <ixy>0</ixy>
            <ixz>0</ixz>
            <iyy>0.00443333</iyy>
            <iyz>0</iyz>
            <izz>0.0072</izz>
          </inertia>
        </inertial>
        <collision name='base_link_collision'>
          <pose>0 0 0 0 -0 0</pose>
          <geometry>
            <mesh>
              <scale>1 1 1</scale>
              <uri>/home/gvnk/assignment2_ws/src/EE413_tutorials/interbotix_xsarm_descriptions/meshes/ur5/collision/Base.dae</uri>
            </mesh>
          </geometry>
          <max_contacts>10</max_contacts>
          <surface>
            <contact>
              <ode/>
            </contact>
            <bounce/>
            <friction>
              <torsional>
                <ode/>
              </torsional>
              <ode/>
            </friction>
          </surface>
        </collision>
        <visual name='base_link_visual'>
          <pose>0 0 0 0 -0 2.35619</pose>
          <geometry>
            <mesh>
              <scale>1 1 1</scale>
              <uri>/home/gvnk/assignment2_ws/src/EE413_tutorials/interbotix_xsarm_descriptions/meshes/ur5/visual/Base.dae</uri>
            </mesh>
          </geometry>
        </visual>
        <self_collide>0</self_collide>
        <enable_wind>0</enable_wind>
        <kinematic>0</kinematic>
      </link>
      <joint name='shoulder_pan_joint' type='revolute'>
        <pose relative_to='base_link'>0 0 0.089159 0 -0 0</pose>
        <parent>base_link</parent>
        <child>shoulder_link</child>
        <axis>
          <xyz>0 0 1</xyz>
          <limit>
            <lower>-6.28319</lower>
            <upper>6.28319</upper>
            <effort>150</effort>
            <velocity>3.14159</velocity>
          </limit>
          <dynamics>
            <damping>0</damping>
            <friction>0</friction>
            <spring_reference>0</spring_reference>
            <spring_stiffness>0</spring_stiffness>
          </dynamics>
        </axis>
      </joint>
      <link name='shoulder_link'>
        <pose relative_to='shoulder_pan_joint'>0 0 0 0 -0 0</pose>
        <inertial>
          <pose>0 0.00193 -0.02561 0 -0 0</pose>
          <mass>3.7</mass>
          <inertia>
            <ixx>0.0102675</ixx>
            <ixy>0</ixy>
            <ixz>0</ixz>
            <iyy>0.0102675</iyy>
            <iyz>0</iyz>
            <izz>0.00666</izz>
          </inertia>
        </inertial>
        <collision name='shoulder_link_collision'>
          <pose>0 0 0 0 -0 0</pose>
          <geometry>
            <mesh>
              <scale>1 1 1</scale>
              <uri>/home/gvnk/assignment2_ws/src/EE413_tutorials/interbotix_xsarm_descriptions/meshes/ur5/collision/Shoulder.dae</uri>
            </mesh>
          </geometry>
          <max_contacts>10</max_contacts>
          <surface>
            <contact>
              <ode/>
            </contact>
            <bounce/>
            <friction>
              <torsional>
                <ode/>
              </torsional>
              <ode/>
            </friction>
          </surface>
        </collision>
        <visual name='shoulder_link_visual'>
          <pose>0 0 0 0 -0 0</pose>
          <geometry>
            <mesh>
              <scale>1 1 1</scale>
              <uri>/home/gvnk/assignment2_ws/src/EE413_tutorials/interbotix_xsarm_descriptions/meshes/ur5/visual/Shoulder.dae</uri>
            </mesh>
          </geometry>
        </visual>
        <self_collide>0</self_collide>
        <enable_wind>0</enable_wind>
        <kinematic>0</kinematic>
      </link>
      <joint name='shoulder_lift_joint' type='revolute'>
        <pose relative_to='shoulder_link'>0 0.13585 0 0 -0 0</pose>
        <parent>shoulder_link</parent>
        <child>upper_arm_link</child>
        <axis>
          <xyz>0 1 0</xyz>
          <limit>
            <lower>-6.28319</lower>
            <upper>6.28319</upper>
            <effort>150</effort>
            <velocity>3.14159</velocity>
          </limit>
          <dynamics>
            <damping>0</damping>
            <friction>0</friction>
            <spring_reference>0</spring_reference>
            <spring_stiffness>0</spring_stiffness>
          </dynamics>
        </axis>
      </joint>
      <link name='upper_arm_link'>
        <pose relative_to='shoulder_lift_joint'>0 0 0 0 -0 0</pose>
        <inertial>
          <pose>0 -0.024201 0.2125 0 -0 0</pose>
          <mass>8.393</mass>
          <inertia>
            <ixx>0.226891</ixx>
            <ixy>0</ixy>
            <ixz>0</ixz>
            <iyy>0.226891</iyy>
            <iyz>0</iyz>
            <izz>0.0151074</izz>
          </inertia>
        </inertial>
        <collision name='upper_arm_link_collision'>
          <pose>0 0 0 0 -0 0</pose>
          <geometry>
            <mesh>
              <scale>1 1 1</scale>
              <uri>/home/gvnk/assignment2_ws/src/EE413_tutorials/interbotix_xsarm_descriptions/meshes/ur5/collision/UpperArm.dae</uri>
            </mesh>
          </geometry>
          <max_contacts>10</max_contacts>
          <surface>
            <contact>
              <ode/>
            </contact>
            <bounce/>
            <friction>
              <torsional>
                <ode/>
              </torsional>
              <ode/>
            </friction>
          </surface>
        </collision>
        <visual name='upper_arm_link_visual'>
          <pose>0 0 0 0 -0 0</pose>
          <geometry>
            <mesh>
              <scale>1 1 1</scale>
              <uri>/home/gvnk/assignment2_ws/src/EE413_tutorials/interbotix_xsarm_descriptions/meshes/ur5/visual/UpperArm.dae</uri>
            </mesh>
          </geometry>
        </visual>
        <self_collide>0</self_collide>
        <enable_wind>0</enable_wind>
        <kinematic>0</kinematic>
      </link>
      <joint name='elbow_joint' type='revolute'>
        <pose relative_to='upper_arm_link'>0 -0.1197 0.425 0 -0 0</pose>
        <parent>upper_arm_link</parent>
        <child>forearm_link</child>
        <axis>
          <xyz>0 1 0</xyz>
          <limit>
            <lower>-6.28319</lower>
            <upper>6.28319</upper>
            <effort>150</effort>
            <velocity>3.14159</velocity>
          </limit>
          <dynamics>
            <damping>0</damping>
            <friction>0</friction>
            <spring_reference>0</spring_reference>
            <spring_stiffness>0</spring_stiffness>
          </dynamics>
        </axis>
      </joint>
      <link name='forearm_link'>
        <pose relative_to='elbow_joint'>0 0 0 0 -0 0</pose>
        <inertial>
          <pose>0 0.0265 0.11993 0 -0 0</pose>
          <mass>2.275</mass>
          <inertia>
            <ixx>0.0494433</ixx>
            <ixy>0</ixy>
            <ixz>0</ixz>
            <iyy>0.0494433</iyy>
            <iyz>0</iyz>
            <izz>0.004095</izz>
          </inertia>
        </inertial>
        <collision name='forearm_link_collision'>
          <pose>0 0 0 0 -0 0</pose>
          <geometry>
            <mesh>
              <scale>1 1 1</scale>
              <uri>/home/gvnk/assignment2_ws/src/EE413_tutorials/interbotix_xsarm_descriptions/meshes/ur5/collision/Forearm.dae</uri>
            </mesh>
          </geometry>
          <max_contacts>10</max_contacts>
          <surface>
            <contact>
              <ode/>
            </contact>
            <bounce/>
            <friction>
              <torsional>
                <ode/>
              </torsional>
              <ode/>
            </friction>
          </surface>
        </collision>
        <visual name='forearm_link_visual'>
          <pose>0 0 0 0 -0 0</pose>
          <geometry>
            <mesh>
              <scale>1 1 1</scale>
              <uri>/home/gvnk/assignment2_ws/src/EE413_tutorials/interbotix_xsarm_descriptions/meshes/ur5/visual/Forearm.dae</uri>
            </mesh>
          </geometry>
        </visual>
        <self_collide>0</self_collide>
        <enable_wind>0</enable_wind>
        <kinematic>0</kinematic>
      </link>
      <joint name='wrist_1_joint' type='revolute'>
        <pose relative_to='forearm_link'>0 0 0.39225 3.14159 1.57079 3.14159</pose>
        <parent>forearm_link</parent>
        <child>wrist_1_link</child>
        <axis>
          <xyz>0 1 0</xyz>
          <limit>
            <lower>-3.14159</lower>
            <upper>4.71</upper>
            <effort>28</effort>
            <velocity>3.14159</velocity>
          </limit>
          <dynamics>
            <damping>0</damping>
            <friction>0</friction>
            <spring_reference>0</spring_reference>
            <spring_stiffness>0</spring_stiffness>
          </dynamics>
        </axis>
      </joint>
      <link name='wrist_1_link'>
        <pose relative_to='wrist_1_joint'>0 0 0 0 -0 0</pose>
        <inertial>
          <pose>0 0.110949 0.01634 0 -0 0</pose>
          <mass>1.219</mass>
          <inertia>
            <ixx>0.111173</ixx>
            <ixy>0</ixy>
            <ixz>0</ixz>
            <iyy>0.111173</iyy>
            <iyz>0</iyz>
            <izz>0.21942</izz>
          </inertia>
        </inertial>
        <collision name='wrist_1_link_collision'>
          <pose>0 0.093 0 3.14159 1.57079 3.14159</pose>
          <geometry>
            <mesh>
              <scale>1 1 1</scale>
              <uri>/home/gvnk/assignment2_ws/src/EE413_tutorials/interbotix_xsarm_descriptions/meshes/ur5/collision/Wrist1.dae</uri>
            </mesh>
          </geometry>
          <max_contacts>10</max_contacts>
          <surface>
            <contact>
              <ode/>
            </contact>
            <bounce/>
            <friction>
              <torsional>
                <ode/>
              </torsional>
              <ode/>
            </friction>
          </surface>
        </collision>
        <visual name='wrist_1_link_visual'>
          <pose>0 0.093 0 3.14159 1.57079 3.14159</pose>
          <geometry>
            <mesh>
              <scale>1 1 1</scale>
              <uri>/home/gvnk/assignment2_ws/src/EE413_tutorials/interbotix_xsarm_descriptions/meshes/ur5/visual/Wrist1.dae</uri>
            </mesh>
          </geometry>
        </visual>
        <self_collide>0</self_collide>
        <enable_wind>0</enable_wind>
        <kinematic>0</kinematic>
      </link>
      <joint name='wrist_2_joint' type='revolute'>
        <pose relative_to='wrist_1_link'>0 0.093 0 0 -0 0</pose>
        <parent>wrist_1_link</parent>
        <child>wrist_2_link</child>
        <axis>
          <xyz>0 0 1</xyz>
          <limit>
            <lower>-3.14159</lower>
            <upper>4.71</upper>
            <effort>28</effort>
            <velocity>3.14159</velocity>
          </limit>
          <dynamics>
            <damping>0</damping>
            <friction>0</friction>
            <spring_reference>0</spring_reference>
            <spring_stiffness>0</spring_stiffness>
          </dynamics>
        </axis>
      </joint>
      <link name='wrist_2_link'>
        <pose relative_to='wrist_2_joint'>0 0 0 0 -0 0</pose>
        <inertial>
          <pose>0 0.0018 0.11099 0 -0 0</pose>
          <mass>1.219</mass>
          <inertia>
            <ixx>0.111173</ixx>
            <ixy>0</ixy>
            <ixz>0</ixz>
            <iyy>0.111173</iyy>
            <iyz>0</iyz>
            <izz>0.21942</izz>
          </inertia>
        </inertial>
        <collision name='wrist_2_link_collision'>
          <pose>0 0 0.09465 0 -0 0</pose>
          <geometry>
            <mesh>
              <scale>1 1 1</scale>
              <uri>/home/gvnk/assignment2_ws/src/EE413_tutorials/interbotix_xsarm_descriptions/meshes/ur5/collision/Wrist2.dae</uri>
            </mesh>
          </geometry>
          <max_contacts>10</max_contacts>
          <surface>
            <contact>
              <ode/>
            </contact>
            <bounce/>
            <friction>
              <torsional>
                <ode/>
              </torsional>
              <ode/>
            </friction>
          </surface>
        </collision>
        <visual name='wrist_2_link_visual'>
          <pose>0 0 0.09465 0 -0 0</pose>
          <geometry>
            <mesh>
              <scale>1 1 1</scale>
              <uri>/home/gvnk/assignment2_ws/src/EE413_tutorials/interbotix_xsarm_descriptions/meshes/ur5/visual/Wrist2.dae</uri>
            </mesh>
          </geometry>
        </visual>
        <self_collide>0</self_collide>
        <enable_wind>0</enable_wind>
        <kinematic>0</kinematic>
      </link>
      <joint name='wrist_3_joint' type='revolute'>
        <pose relative_to='wrist_2_link'>0 0 0.09465 0 -0 0</pose>
        <parent>wrist_2_link</parent>
        <child>wrist_3_link</child>
        <axis>
          <xyz>0 1 0</xyz>
          <limit>
            <lower>-3.14159</lower>
            <upper>3.14159</upper>
            <effort>28</effort>
            <velocity>3.14159</velocity>
          </limit>
          <dynamics>
            <damping>0</damping>
            <friction>0</friction>
            <spring_reference>0</spring_reference>
            <spring_stiffness>0</spring_stiffness>
          </dynamics>
        </axis>
      </joint>
      <link name='wrist_3_link'>
        <pose relative_to='wrist_3_joint'>0 0 0 0 -0 0</pose>
        <inertial>
          <pose>0 0.065129 0 0 -0 0</pose>
          <mass>0.8879</mass>
          <inertia>
            <ixx>0.0191118</ixx>
            <ixy>-1e-06</ixy>
            <ixz>1e-06</ixz>
            <iyy>0.0181365</iyy>
            <iyz>-1e-06</iyz>
            <izz>0.0357973</izz>
          </inertia>
        </inertial>
        <collision name='wrist_3_link_collision'>
          <pose>0 0 0 0 -0 0</pose>
          <geometry>
            <mesh>
              <scale>1 1 1</scale>
              <uri>/home/gvnk/assignment2_ws/src/EE413_tutorials/interbotix_xsarm_descriptions/meshes/ur5/collision/Wrist3.dae</uri>
            </mesh>
          </geometry>
          <max_contacts>10</max_contacts>
          <surface>
            <contact>
              <ode/>
            </contact>
            <bounce/>
            <friction>
              <torsional>
                <ode/>
              </torsional>
              <ode/>
            </friction>
          </surface>
        </collision>
        <collision name='wrist_3_link_fixed_joint_lump__onrobot_rg2_base_link_collision_1'>
          <pose>0 0.0823 0 1.57079 1.57079 3.14159</pose>
          <geometry>
            <mesh>
              <scale>1 1 1</scale>
              <uri>/home/gvnk/assignment2_ws/src/EE413_tutorials/interbotix_xsarm_descriptions/meshes/ur5/collision/base_link.stl</uri>
            </mesh>
          </geometry>
          <max_contacts>10</max_contacts>
          <surface>
            <contact>
              <ode/>
            </contact>
            <bounce/>
            <friction>
              <torsional>
                <ode/>
              </torsional>
              <ode/>
            </friction>
          </surface>
        </collision>
        <visual name='wrist_3_link_visual'>
          <pose>0 0 0 0 -0 0</pose>
          <geometry>
            <mesh>
              <scale>1 1 1</scale>
              <uri>/home/gvnk/assignment2_ws/src/EE413_tutorials/interbotix_xsarm_descriptions/meshes/ur5/visual/Wrist3.dae</uri>
            </mesh>
          </geometry>
        </visual>
        <visual name='wrist_3_link_fixed_joint_lump__onrobot_rg2_base_link_visual_1'>
          <pose>0 0.0823 0 1.57079 1.57079 3.14159</pose>
          <geometry>
            <mesh>
              <scale>1 1 1</scale>
              <uri>/home/gvnk/assignment2_ws/src/EE413_tutorials/interbotix_xsarm_descriptions/meshes/ur5/visual/base_link.stl</uri>
            </mesh>
          </geometry>
        </visual>
        <self_collide>0</self_collide>
        <enable_wind>0</enable_wind>
        <kinematic>0</kinematic>
      </link>
      <joint name='finger_joint' type='revolute'>
        <pose relative_to='wrist_3_link'>0.017178 0.208097 -0 3.14159 1.57079 -1.5708</pose>
        <parent>wrist_3_link</parent>
        <child>left_outer_knuckle</child>
        <axis>
          <xyz>-1 0 0</xyz>
          <limit>
            <lower>-0.558505</lower>
            <upper>0.785398</upper>
            <effort>1000</effort>
            <velocity>100</velocity>
          </limit>
          <dynamics>
            <spring_reference>0</spring_reference>
            <spring_stiffness>0</spring_stiffness>
          </dynamics>
        </axis>
      </joint>
      <link name='left_outer_knuckle'>
        <pose relative_to='finger_joint'>0 0 0 0 -0 0</pose>
        <inertial>
          <pose>0 0 0 0 -0 0</pose>
          <mass>0.05</mass>
          <inertia>
            <ixx>0.001</ixx>
            <ixy>1e-06</ixy>
            <ixz>1e-06</ixz>
            <iyy>0.001</iyy>
            <iyz>1e-06</iyz>
            <izz>0.001</izz>
          </inertia>
        </inertial>
        <collision name='left_outer_knuckle_collision'>
          <pose>0 0 0 0 -0 0</pose>
          <geometry>
            <mesh>
              <scale>1 1 1</scale>
              <uri>/home/gvnk/assignment2_ws/src/EE413_tutorials/interbotix_xsarm_descriptions/meshes/ur5/collision/outer_knuckle.stl</uri>
            </mesh>
          </geometry>
          <max_contacts>10</max_contacts>
          <surface>
            <contact>
              <ode/>
            </contact>
            <bounce/>
            <friction>
              <torsional>
                <ode/>
              </torsional>
              <ode/>
            </friction>
          </surface>
        </collision>
        <visual name='left_outer_knuckle_visual'>
          <pose>0 0 0 0 -0 0</pose>
          <geometry>
            <mesh>
              <scale>1 1 1</scale>
              <uri>/home/gvnk/assignment2_ws/src/EE413_tutorials/interbotix_xsarm_descriptions/meshes/ur5/visual/outer_knuckle.stl</uri>
            </mesh>
          </geometry>
        </visual>
        <self_collide>0</self_collide>
        <enable_wind>0</enable_wind>
        <kinematic>0</kinematic>
      </link>
      <joint name='left_inner_finger_joint' type='revolute'>
        <pose relative_to='left_outer_knuckle'>0 -0.039592 0.038177 0 -0 0</pose>
        <parent>left_outer_knuckle</parent>
        <child>left_inner_finger</child>
        <axis>
          <xyz>1 0 0</xyz>
          <limit>
            <lower>-0.872665</lower>
            <upper>0.872665</upper>
            <effort>1000</effort>
            <velocity>100</velocity>
          </limit>
          <dynamics>
            <spring_reference>0</spring_reference>
            <spring_stiffness>0</spring_stiffness>
          </dynamics>
        </axis>
      </joint>
      <link name='left_inner_finger'>
        <pose relative_to='left_inner_finger_joint'>0 0 0 0 -0 0</pose>
        <inertial>
          <pose>0 0 0 0 -0 0</pose>
          <mass>0.05</mass>
          <inertia>
            <ixx>0.001</ixx>
            <ixy>1e-06</ixy>
            <ixz>1e-06</ixz>
            <iyy>0.001</iyy>
            <iyz>1e-06</iyz>
            <izz>0.001</izz>
          </inertia>
        </inertial>
        <collision name='left_inner_finger_collision'>
          <pose>0 0 0 0 -0 0</pose>
          <geometry>
            <mesh>
              <scale>1 1 1</scale>
              <uri>/home/gvnk/assignment2_ws/src/EE413_tutorials/interbotix_xsarm_descriptions/meshes/ur5/collision/inner_finger.stl</uri>
            </mesh>
          </geometry>
          <max_contacts>10</max_contacts>
          <surface>
            <contact>
              <ode/>
            </contact>
            <bounce/>
            <friction>
              <torsional>
                <ode/>
              </torsional>
              <ode/>
            </friction>
          </surface>
        </collision>
        <visual name='left_inner_finger_visual'>
          <pose>0 0 0 0 -0 0</pose>
          <geometry>
            <mesh>
              <scale>1 1 1</scale>
              <uri>/home/gvnk/assignment2_ws/src/EE413_tutorials/interbotix_xsarm_descriptions/meshes/ur5/visual/inner_finger.stl</uri>
            </mesh>
          </geometry>
        </visual>
        <self_collide>0</self_collide>
        <enable_wind>0</enable_wind>
        <kinematic>0</kinematic>
      </link>
      <joint name='left_inner_knuckle_joint' type='revolute'>
        <pose relative_to='wrist_3_link'>0.007678 0.224597 -1e-06 3.14159 1.57079 -1.5708</pose>
        <parent>wrist_3_link</parent>
        <child>left_inner_knuckle</child>
        <axis>
          <xyz>1 0 0</xyz>
          <limit>
            <lower>-0.785398</lower>
            <upper>0.785398</upper>
            <effort>1000</effort>
            <velocity>100</velocity>
          </limit>
          <dynamics>
            <spring_reference>0</spring_reference>
            <spring_stiffness>0</spring_stiffness>
          </dynamics>
        </axis>
      </joint>
      <link name='left_inner_knuckle'>
        <pose relative_to='left_inner_knuckle_joint'>0 0 0 0 -0 0</pose>
        <inertial>
          <pose>0 0 0 0 -0 0</pose>
          <mass>0.05</mass>
          <inertia>
            <ixx>0.001</ixx>
            <ixy>1e-06</ixy>
            <ixz>1e-06</ixz>
            <iyy>0.001</iyy>
            <iyz>1e-06</iyz>
            <izz>0.001</izz>
          </inertia>
        </inertial>
        <collision name='left_inner_knuckle_collision'>
          <pose>0 0 0 0 -0 0</pose>
          <geometry>
            <mesh>
              <scale>1 1 1</scale>
              <uri>/home/gvnk/assignment2_ws/src/EE413_tutorials/interbotix_xsarm_descriptions/meshes/ur5/collision/inner_knuckle.stl</uri>
            </mesh>
          </geometry>
          <max_contacts>10</max_contacts>
          <surface>
            <contact>
              <ode/>
            </contact>
            <bounce/>
            <friction>
              <torsional>
                <ode/>
              </torsional>
              <ode/>
            </friction>
          </surface>
        </collision>
        <visual name='left_inner_knuckle_visual'>
          <pose>0 0 0 0 -0 0</pose>
          <geometry>
            <mesh>
              <scale>1 1 1</scale>
              <uri>/home/gvnk/assignment2_ws/src/EE413_tutorials/interbotix_xsarm_descriptions/meshes/ur5/visual/inner_knuckle.stl</uri>
            </mesh>
          </geometry>
        </visual>
        <self_collide>0</self_collide>
        <enable_wind>0</enable_wind>
        <kinematic>0</kinematic>
      </link>
      <joint name='right_inner_knuckle_joint' type='revolute'>
        <pose relative_to='wrist_3_link'>-0.007678 0.224597 -1e-06 -3.14159 -1.57079 1.5708</pose>
        <parent>wrist_3_link</parent>
        <child>right_inner_knuckle</child>
        <axis>
          <xyz>1 0 0</xyz>
          <limit>
            <lower>-0.785398</lower>
            <upper>0.785398</upper>
            <effort>1000</effort>
            <velocity>100</velocity>
          </limit>
          <dynamics>
            <spring_reference>0</spring_reference>
            <spring_stiffness>0</spring_stiffness>
          </dynamics>
        </axis>
      </joint>
      <link name='right_inner_knuckle'>
        <pose relative_to='right_inner_knuckle_joint'>0 0 0 0 -0 0</pose>
        <inertial>
          <pose>0 0 0 0 -0 0</pose>
          <mass>0.05</mass>
          <inertia>
            <ixx>0.001</ixx>
            <ixy>1e-06</ixy>
            <ixz>1e-06</ixz>
            <iyy>0.001</iyy>
            <iyz>1e-06</iyz>
            <izz>0.001</izz>
          </inertia>
        </inertial>
        <collision name='right_inner_knuckle_collision'>
          <pose>0 0 0 0 -0 0</pose>
          <geometry>
            <mesh>
              <scale>1 1 1</scale>
              <uri>/home/gvnk/assignment2_ws/src/EE413_tutorials/interbotix_xsarm_descriptions/meshes/ur5/collision/inner_knuckle.stl</uri>
            </mesh>
          </geometry>
          <max_contacts>10</max_contacts>
          <surface>
            <contact>
              <ode/>
            </contact>
            <bounce/>
            <friction>
              <torsional>
                <ode/>
              </torsional>
              <ode/>
            </friction>
          </surface>
        </collision>
        <visual name='right_inner_knuckle_visual'>
          <pose>0 0 0 0 -0 0</pose>
          <geometry>
            <mesh>
              <scale>1 1 1</scale>
              <uri>/home/gvnk/assignment2_ws/src/EE413_tutorials/interbotix_xsarm_descriptions/meshes/ur5/visual/inner_knuckle.stl</uri>
            </mesh>
          </geometry>
        </visual>
        <self_collide>0</self_collide>
        <enable_wind>0</enable_wind>
        <kinematic>0</kinematic>
      </link>
      <joint name='right_outer_knuckle_joint' type='revolute'>
        <pose relative_to='wrist_3_link'>-0.017178 0.208097 -0 3.14159 -1.57079 1.5708</pose>
        <parent>wrist_3_link</parent>
        <child>right_outer_knuckle</child>
        <axis>
          <xyz>1 0 0</xyz>
          <limit>
            <lower>-0.785398</lower>
            <upper>0.785398</upper>
            <effort>1000</effort>
            <velocity>100</velocity>
          </limit>
          <dynamics>
            <spring_reference>0</spring_reference>
            <spring_stiffness>0</spring_stiffness>
          </dynamics>
        </axis>
      </joint>
      <link name='right_outer_knuckle'>
        <pose relative_to='right_outer_knuckle_joint'>0 0 0 0 -0 0</pose>
        <inertial>
          <pose>0 0 0 0 -0 0</pose>
          <mass>0.05</mass>
          <inertia>
            <ixx>0.001</ixx>
            <ixy>1e-06</ixy>
            <ixz>1e-06</ixz>
            <iyy>0.001</iyy>
            <iyz>1e-06</iyz>
            <izz>0.001</izz>
          </inertia>
        </inertial>
        <collision name='right_outer_knuckle_collision'>
          <pose>0 0 0 0 -0 0</pose>
          <geometry>
            <mesh>
              <scale>1 1 1</scale>
              <uri>/home/gvnk/assignment2_ws/src/EE413_tutorials/interbotix_xsarm_descriptions/meshes/ur5/collision/outer_knuckle.stl</uri>
            </mesh>
          </geometry>
          <max_contacts>10</max_contacts>
          <surface>
            <contact>
              <ode/>
            </contact>
            <bounce/>
            <friction>
              <torsional>
                <ode/>
              </torsional>
              <ode/>
            </friction>
          </surface>
        </collision>
        <visual name='right_outer_knuckle_visual'>
          <pose>0 0 0 0 -0 0</pose>
          <geometry>
            <mesh>
              <scale>1 1 1</scale>
              <uri>/home/gvnk/assignment2_ws/src/EE413_tutorials/interbotix_xsarm_descriptions/meshes/ur5/visual/outer_knuckle.stl</uri>
            </mesh>
          </geometry>
        </visual>
        <self_collide>0</self_collide>
        <enable_wind>0</enable_wind>
        <kinematic>0</kinematic>
      </link>
      <joint name='right_inner_finger_joint' type='revolute'>
        <pose relative_to='right_outer_knuckle'>0 -0.039592 0.038177 0 -0 0</pose>
        <parent>right_outer_knuckle</parent>
        <child>right_inner_finger</child>
        <axis>
          <xyz>1 0 0</xyz>
          <limit>
            <lower>-0.872665</lower>
            <upper>0.872665</upper>
            <effort>1000</effort>
            <velocity>100</velocity>
          </limit>
          <dynamics>
            <spring_reference>0</spring_reference>
            <spring_stiffness>0</spring_stiffness>
          </dynamics>
        </axis>
      </joint>
      <link name='right_inner_finger'>
        <pose relative_to='right_inner_finger_joint'>0 0 0 0 -0 0</pose>
        <inertial>
          <pose>0 0 0 0 -0 0</pose>
          <mass>0.05</mass>
          <inertia>
            <ixx>0.001</ixx>
            <ixy>1e-06</ixy>
            <ixz>1e-06</ixz>
            <iyy>0.001</iyy>
            <iyz>1e-06</iyz>
            <izz>0.001</izz>
          </inertia>
        </inertial>
        <collision name='right_inner_finger_collision'>
          <pose>0 0 0 0 -0 0</pose>
          <geometry>
            <mesh>
              <scale>1 1 1</scale>
              <uri>/home/gvnk/assignment2_ws/src/EE413_tutorials/interbotix_xsarm_descriptions/meshes/ur5/collision/inner_finger.stl</uri>
            </mesh>
          </geometry>
          <max_contacts>10</max_contacts>
          <surface>
            <contact>
              <ode/>
            </contact>
            <bounce/>
            <friction>
              <torsional>
                <ode/>
              </torsional>
              <ode/>
            </friction>
          </surface>
        </collision>
        <visual name='right_inner_finger_visual'>
          <pose>0 0 0 0 -0 0</pose>
          <geometry>
            <mesh>
              <scale>1 1 1</scale>
              <uri>/home/gvnk/assignment2_ws/src/EE413_tutorials/interbotix_xsarm_descriptions/meshes/ur5/visual/inner_finger.stl</uri>
            </mesh>
          </geometry>
        </visual>
        <self_collide>0</self_collide>
        <enable_wind>0</enable_wind>
        <kinematic>0</kinematic>
      </link>
      <plugin name='gazebo_ros_control' filename='libgazebo_ros_control.so'>
        <robotNamespace>/</robotNamespace>
      </plugin>
      <static>0</static>
      <plugin name='gazebo_grasp_fix' filename='libgazebo_grasp_fix.so'>
        <arm>
          <arm_name>ur5_arm_robot</arm_name>
          <palm_link>wrist_3_link</palm_link>
          <gripper_link>left_outer_knuckle</gripper_link>
          <gripper_link>right_outer_knuckle</gripper_link>
          <gripper_link>left_inner_knuckle</gripper_link>
          <gripper_link>right_inner_knuckle</gripper_link>
          <gripper_link>left_inner_finger</gripper_link>
          <gripper_link>right_inner_finger</gripper_link>
        </arm>
        <forces_angle_tolerance>100</forces_angle_tolerance>
        <update_rate>4</update_rate>
        <grip_count_threshold>4</grip_count_threshold>
        <max_grip_count>8</max_grip_count>
        <release_tolerance>0.005</release_tolerance>
        <disable_collisions_on_attach>0</disable_collisions_on_attach>
        <contact_topic>__default_topic__</contact_topic>
        <robotNamespace>/</robotNamespace>
      </plugin>
      <pose>0 0 0 0 -0 0</pose>
    </model>
  </world>
</sdf>
